Traceback (most recent call last):
  File "/Users/kyeongeunchoi/.local/share/virtualenvs/first_flask_mysql-Ix3rWjVL/lib/python3.10/site-packages/flask/app.py", line 2091, in __call__
    return self.wsgi_app(environ, start_response)
  File "/Users/kyeongeunchoi/.local/share/virtualenvs/first_flask_mysql-Ix3rWjVL/lib/python3.10/site-packages/flask/app.py", line 2076, in wsgi_app
    response = self.handle_exception(e)
  File "/Users/kyeongeunchoi/.local/share/virtualenvs/first_flask_mysql-Ix3rWjVL/lib/python3.10/site-packages/flask/app.py", line 2073, in wsgi_app
    response = self.full_dispatch_request()
  File "/Users/kyeongeunchoi/.local/share/virtualenvs/first_flask_mysql-Ix3rWjVL/lib/python3.10/site-packages/flask/app.py", line 1518, in full_dispatch_request
    rv = self.handle_user_exception(e)
  File "/Users/kyeongeunchoi/.local/share/virtualenvs/first_flask_mysql-Ix3rWjVL/lib/python3.10/site-packages/flask/app.py", line 1516, in full_dispatch_request
    rv = self.dispatch_request()
  File "/Users/kyeongeunchoi/.local/share/virtualenvs/first_flask_mysql-Ix3rWjVL/lib/python3.10/site-packages/flask/app.py", line 1502, in dispatch_request
    return self.ensure_sync(self.view_functions[rule.endpoint])(**req.view_args)
  File "/Users/kyeongeunchoi/dojo/PythonCourse/PythonFun/python/flask_mysql/db_connection/first_flask_mysql/server.py", line 9, in index
    friends = Friend.get_all()
  File "/Users/kyeongeunchoi/dojo/PythonCourse/PythonFun/python/flask_mysql/db_connection/first_flask_mysql/friend.py", line 15, in get_all
    results = connectToMySQL('first_flask').query_db(query)
  File "/Users/kyeongeunchoi/dojo/PythonCourse/PythonFun/python/flask_mysql/db_connection/first_flask_mysql/mysqlconnection.py", line 38, in connectToMySQL
    return MySQLConnection(db)
  File "/Users/kyeongeunchoi/dojo/PythonCourse/PythonFun/python/flask_mysql/db_connection/first_flask_mysql/mysqlconnection.py", line 4, in __init__
    connection = pymysql.connect(host = '127.0.0.1',
  File "/Users/kyeongeunchoi/.local/share/virtualenvs/first_flask_mysql-Ix3rWjVL/lib/python3.10/site-packages/pymysql/connections.py", line 353, in __init__
    self.connect()
  File "/Users/kyeongeunchoi/.local/share/virtualenvs/first_flask_mysql-Ix3rWjVL/lib/python3.10/site-packages/pymysql/connections.py", line 633, in connect
    self._request_authentication()
  File "/Users/kyeongeunchoi/.local/share/virtualenvs/first_flask_mysql-Ix3rWjVL/lib/python3.10/site-packages/pymysql/connections.py", line 907, in _request_authentication
    auth_packet = self._read_packet()
  File "/Users/kyeongeunchoi/.local/share/virtualenvs/first_flask_mysql-Ix3rWjVL/lib/python3.10/site-packages/pymysql/connections.py", line 725, in _read_packet
    packet.raise_for_error()
  File "/Users/kyeongeunchoi/.local/share/virtualenvs/first_flask_mysql-Ix3rWjVL/lib/python3.10/site-packages/pymysql/protocol.py", line 221, in raise_for_error
    err.raise_mysql_exception(self._data)
  File "/Users/kyeongeunchoi/.local/share/virtualenvs/first_flask_mysql-Ix3rWjVL/lib/python3.10/site-packages/pymysql/err.py", line 143, in raise_mysql_exception
    raise errorclass(errno, errval)
pymysql.err.OperationalError: (1049, "Unknown database 'first_flask'")

=========== I used wrong database name (database name is 'first_flask_mysql'))

Traceback (most recent call last):
  File "/Users/kyeongeunchoi/.local/share/virtualenvs/first_flask_mysql-Ix3rWjVL/lib/python3.10/site-packages/flask/app.py", line 2091, in __call__
    return self.wsgi_app(environ, start_response)
  File "/Users/kyeongeunchoi/.local/share/virtualenvs/first_flask_mysql-Ix3rWjVL/lib/python3.10/site-packages/flask/app.py", line 2076, in wsgi_app
    response = self.handle_exception(e)
  File "/Users/kyeongeunchoi/.local/share/virtualenvs/first_flask_mysql-Ix3rWjVL/lib/python3.10/site-packages/flask/app.py", line 2073, in wsgi_app
    response = self.full_dispatch_request()
  File "/Users/kyeongeunchoi/.local/share/virtualenvs/first_flask_mysql-Ix3rWjVL/lib/python3.10/site-packages/flask/app.py", line 1518, in full_dispatch_request
    rv = self.handle_user_exception(e)
  File "/Users/kyeongeunchoi/.local/share/virtualenvs/first_flask_mysql-Ix3rWjVL/lib/python3.10/site-packages/flask/app.py", line 1516, in full_dispatch_request
    rv = self.dispatch_request()
  File "/Users/kyeongeunchoi/.local/share/virtualenvs/first_flask_mysql-Ix3rWjVL/lib/python3.10/site-packages/flask/app.py", line 1502, in dispatch_request
    return self.ensure_sync(self.view_functions[rule.endpoint])(**req.view_args)
  File "/Users/kyeongeunchoi/dojo/PythonCourse/PythonFun/python/flask_mysql/db_connection/first_flask_mysql/server.py", line 9, in index
    friends = Friend.get_all()
  File "/Users/kyeongeunchoi/dojo/PythonCourse/PythonFun/python/flask_mysql/db_connection/first_flask_mysql/friend.py", line 15, in get_all
    results = connectToMySQL('first_flask_mysql').query_db(query)
  File "/Users/kyeongeunchoi/dojo/PythonCourse/PythonFun/python/flask_mysql/db_connection/first_flask_mysql/mysqlconnection.py", line 14, in query_db
    with self.connction.cursor() as cursor:
AttributeError: 'MySQLConnection' object has no attribute 'connction'

=========== I made some misspell. 

Traceback (most recent call last):
  File "/Users/kyeongeunchoi/.local/share/virtualenvs/first_flask_mysql-Ix3rWjVL/lib/python3.10/site-packages/flask/app.py", line 2091, in __call__
    return self.wsgi_app(environ, start_response)
  File "/Users/kyeongeunchoi/.local/share/virtualenvs/first_flask_mysql-Ix3rWjVL/lib/python3.10/site-packages/flask/app.py", line 2076, in wsgi_app
    response = self.handle_exception(e)
  File "/Users/kyeongeunchoi/.local/share/virtualenvs/first_flask_mysql-Ix3rWjVL/lib/python3.10/site-packages/flask/app.py", line 2073, in wsgi_app
    response = self.full_dispatch_request()
  File "/Users/kyeongeunchoi/.local/share/virtualenvs/first_flask_mysql-Ix3rWjVL/lib/python3.10/site-packages/flask/app.py", line 1518, in full_dispatch_request
    rv = self.handle_user_exception(e)
  File "/Users/kyeongeunchoi/.local/share/virtualenvs/first_flask_mysql-Ix3rWjVL/lib/python3.10/site-packages/flask/app.py", line 1516, in full_dispatch_request
    rv = self.dispatch_request()
  File "/Users/kyeongeunchoi/.local/share/virtualenvs/first_flask_mysql-Ix3rWjVL/lib/python3.10/site-packages/flask/app.py", line 1502, in dispatch_request
    return self.ensure_sync(self.view_functions[rule.endpoint])(**req.view_args)
  File "/Users/kyeongeunchoi/dojo/PythonCourse/PythonFun/python/flask_mysql/db_connection/first_flask_mysql/server.py", line 9, in index
    friends = Friend.get_all()
  File "/Users/kyeongeunchoi/dojo/PythonCourse/PythonFun/python/flask_mysql/db_connection/first_flask_mysql/friend.py", line 19, in get_all
    friends.append( cls(friend) )
  File "/Users/kyeongeunchoi/dojo/PythonCourse/PythonFun/python/flask_mysql/db_connection/first_flask_mysql/friend.py", line 5, in __init__
    self.id = data['id']
KeyError: 'id'

Traceback (most recent call last):
  File "/Users/kyeongeunchoi/.local/share/virtualenvs/first_flask_mysql-Ix3rWjVL/lib/python3.10/site-packages/flask/app.py", line 2091, in __call__
    return self.wsgi_app(environ, start_response)
  File "/Users/kyeongeunchoi/.local/share/virtualenvs/first_flask_mysql-Ix3rWjVL/lib/python3.10/site-packages/flask/app.py", line 2076, in wsgi_app
    response = self.handle_exception(e)
  File "/Users/kyeongeunchoi/.local/share/virtualenvs/first_flask_mysql-Ix3rWjVL/lib/python3.10/site-packages/flask/app.py", line 2073, in wsgi_app
    response = self.full_dispatch_request()
  File "/Users/kyeongeunchoi/.local/share/virtualenvs/first_flask_mysql-Ix3rWjVL/lib/python3.10/site-packages/flask/app.py", line 1518, in full_dispatch_request
    rv = self.handle_user_exception(e)
  File "/Users/kyeongeunchoi/.local/share/virtualenvs/first_flask_mysql-Ix3rWjVL/lib/python3.10/site-packages/flask/app.py", line 1516, in full_dispatch_request
    rv = self.dispatch_request()
  File "/Users/kyeongeunchoi/.local/share/virtualenvs/first_flask_mysql-Ix3rWjVL/lib/python3.10/site-packages/flask/app.py", line 1502, in dispatch_request
    return self.ensure_sync(self.view_functions[rule.endpoint])(**req.view_args)
  File "/Users/kyeongeunchoi/dojo/PythonCourse/PythonFun/python/flask_mysql/db_connection/first_flask_mysql/server.py", line 9, in index
    friends = Friend.get_all()
  File "/Users/kyeongeunchoi/dojo/PythonCourse/PythonFun/python/flask_mysql/db_connection/first_flask_mysql/friend.py", line 19, in get_all
    friends.append( cls(friend) )
  File "/Users/kyeongeunchoi/dojo/PythonCourse/PythonFun/python/flask_mysql/db_connection/first_flask_mysql/friend.py", line 9, in __init__
    self.create_at = data['create_at']
KeyError: 'create_at'